<?xml version='1.0'?>

<robot name="robot" xmlns:xacro="http://www.ros.org/wiki/xacro">

  <xacro:property name="chassis_width" value="0.15"/>
  <xacro:property name="chassis_length" value="0.2"/>
  <xacro:property name="chassis_height" value="0.05"/>
  <xacro:property name="chassis_mass" value=".5"/>
  <xacro:property name="wheel_radius" value="0.04"/>
  <xacro:property name="wheel_width" value="0.03"/>
 <xacro:property name="camera_link" value="0.05" /> <!-- Size of square 'camera' box -->

  <xacro:include filename="$(find enph353_ros_lab)/urdf/macros.xacro" />


  <link name='chassis'>

    <xacro:box_inertial name="chassis" m="${chassis_mass}" x="${chassis_length}" y="${chassis_width}" z="${chassis_height}"/>

    <collision name='chassis_collision'>
      <geometry>
        <box size="${chassis_length} ${chassis_width} ${chassis_height}"/>
      </geometry>
    </collision>

    <visual name='chassis_visual'>
      <origin xyz="0 0 0" rpy=" 0 0 0"/>
      <geometry>
        <box size="${chassis_length} ${chassis_width} ${chassis_height}"/>
      </geometry>
      <surface>
        <friction>
          <ode>
            <mu>0.1</mu>
            <mu2>0.1</mu2>
          </ode>
        </friction>
      </surface>
    </visual>

  </link>


<link name='wheel1'>
	<xacro:cylinder_inertial name="wheel1" m=".01" r ="${wheel_radius}" h="${wheel_width}" />

   <collision name='wheel1'>
      <geometry>
        <cylinder length="${wheel_width}" radius="${wheel_radius}"/>
      </geometry>
      <surface>
        <friction>
          <ode>
            <mu>.1</mu>
            <mu2>.1</mu2>
          </ode>
        </friction>
      </surface>
<origin rpy="1.57075 0 0" xyz="0 0 0"/>
    </collision>

   <visual>
      <origin rpy="1.57075 0 0" xyz="0 0 0"/>
      <geometry>
        <cylinder length="${wheel_width}" radius="${wheel_radius}"/>
      </geometry>
    </visual>	
</link>

<link name='wheel2'>
	<xacro:cylinder_inertial name="wheel2" m=".01" r ="${wheel_radius}" h="${wheel_width}" />

   <collision name='wheel1'>
      <geometry>
        <cylinder length="${wheel_width}" radius="${wheel_radius}"/>
      </geometry>
      <surface>
        <friction>
          <ode>
            <mu>.1</mu>
            <mu2>.1</mu2>
          </ode>
        </friction>
      </surface>
    </collision>

   <visual>
      <origin rpy="1.57075 0 0" xyz="0 0 0"/>
      <geometry>
        <cylinder length="${wheel_width}" radius="${wheel_radius}"/>
      </geometry>
<origin rpy="1.57075 0 0" xyz="0 0 0"/>
    </visual>	
</link>

<link name='wheel3'>
	<xacro:cylinder_inertial name="wheel3" m=".01" r ="${wheel_radius}" h="${wheel_width}" />

   <collision name='wheel1'>
      <geometry>
        <cylinder length="${wheel_width}" radius="${wheel_radius}"/>
      </geometry>
      <surface>
        <friction>
          <ode>
            <mu>.1</mu>
            <mu2>.1</mu2>
          </ode>
        </friction>
      </surface>
<origin rpy="1.57075 0 0" xyz="0 0 0"/>
    </collision>

   <visual>
      <origin rpy="1.57075 0 0" xyz="0 0 0"/>
      <geometry>
        <cylinder length="${wheel_width}" radius="${wheel_radius}"/>
      </geometry>
<origin rpy="1.57075 0 0" xyz="0 0 0"/>
    </visual>	
</link>

<link name='wheel4'>
	<xacro:cylinder_inertial name="wheel1" m=".01" r ="${wheel_radius}" h="${wheel_width}" />

   <collision name='wheel4'>
      <geometry>
        <cylinder length="${wheel_width}" radius="${wheel_radius}"/>
      </geometry>
      <surface>
        <friction>
          <ode>
            <mu>.1</mu>
            <mu2>.1</mu2>
          </ode>
        </friction>
      </surface>
<origin rpy="1.57075 0 0" xyz="0 0 0"/>
    </collision>

   <visual>
      <origin rpy="1.57075 0 0" xyz="0 0 0"/>
      <geometry>
        <cylinder length="${wheel_width}" radius="${wheel_radius}"/>
      </geometry>
    </visual>	
</link>

  <joint name="joint1" type="continuous">
<axis xyz=" 0 1 0"/>
    <parent link="chassis"/>
    <child link="wheel1"/>
    <origin xyz=".1 .09 0" rpy="0 0 0" />
  </joint>

  <joint name="joint2" type="continuous">
<axis xyz=" 0 1 0"/>
    <parent link="chassis"/>
    <child link="wheel2"/>
    <origin xyz="-.1 .09 0" rpy="0 0 0" />
  </joint>

  <joint name="joint3" type="continuous">
<axis xyz=" 0 1 0"/>
    <parent link="chassis"/>
    <child link="wheel3"/>
    <origin xyz=".1 -.09 0" rpy="0 0 0" />
  </joint>

  <joint name="joint4" type="continuous">
    <axis xyz=" 0 1 0"/>
    <parent link="chassis"/>
    <child link="wheel4"/>
    <origin xyz="-.1 -.09 0" rpy="0 0 0" />
  </joint>

<gazebo>
  <plugin name="skid_steer_drive_controller" filename="libgazebo_ros_skid_steer_drive.so">
    <updateRate>100.0</updateRate>
    <robotNamespace>/</robotNamespace>
    <leftFrontJoint>joint1</leftFrontJoint>
    <rightFrontJoint>joint3</rightFrontJoint>
    <leftRearJoint>joint2</leftRearJoint>
    <rightRearJoint>joint4</rightRearJoint>
    <wheelSeparation>.18</wheelSeparation>
    <wheelDiameter>0.08</wheelDiameter>
    <robotBaseFrame>base_link</robotBaseFrame>
    <torque>20</torque>
    <topicName>cmd_vel</topicName>
    <broadcastTF>false</broadcastTF>
  </plugin>
</gazebo>


<joint name="camera_joint" type="fixed">
    <axis xyz="0 1 0" />
    <origin xyz=".1 0 .05" rpy="0 0.5 0"/>
    <parent link="chassis"/>
    <child link="camera_link"/>
  </joint>

  <!-- Camera -->
  <link name="camera_link">
    <collision>
      <origin xyz="0 0 0" rpy="0 0 0"/>
      <geometry>
    <box size="${camera_link} ${camera_link} ${camera_link}"/>
      </geometry>
    </collision>

    <visual>
      <origin xyz="0 0 0" rpy="0 0 0"/>
      <geometry>
    <box size="${camera_link} ${camera_link} ${camera_link}"/>
      </geometry>
      <material name="red"/>
    </visual>

    <inertial>
      <mass value="1e-5" />
      <origin xyz="0 0 0" rpy="0 0 0"/>
      <inertia ixx="1e-6" ixy="0" ixz="0" iyy="1e-6" iyz="0" izz="1e-6" />
    </inertial>
  </link>




 <!-- camera -->
  <gazebo reference="camera_link">
    <sensor type="camera" name="camera1">
      <update_rate>30.0</update_rate>
      <camera name="head">
        <horizontal_fov>1.3962634</horizontal_fov>
        <image>
          <width>800</width>
          <height>800</height>
          <format>R8G8B8</format>
        </image>
        <clip>
          <near>0.02</near>
          <far>300</far>
        </clip>
        <noise>
          <type>gaussian</type>
          <!-- Noise is sampled independently per pixel on each frame.
               That pixel's noise value is added to each of its color
               channels, which at that point lie in the range [0,1]. -->
          <mean>0.0</mean>
          <stddev>0.007</stddev>
        </noise>
      </camera>
      <plugin name="camera_controller" filename="libgazebo_ros_camera.so">
        <alwaysOn>true</alwaysOn>
        <updateRate>0.0</updateRate>
        <cameraName>rrbot/camera1</cameraName>
        <imageTopicName>image_raw</imageTopicName>
        <cameraInfoTopicName>camera_info</cameraInfoTopicName>
        <frameName>camera_link</frameName>
        <hackBaseline>0.07</hackBaseline>
        <distortionK1>0.0</distortionK1>
        <distortionK2>0.0</distortionK2>
        <distortionK3>0.0</distortionK3>
        <distortionT1>0.0</distortionT1>
        <distortionT2>0.0</distortionT2>
      </plugin>
    </sensor>
  </gazebo>

</robot>
